Workbook

Sheet Diagnóstico
B1: DIAGNÓSTICO EMPRESARIAL
C2: QUESTIONÁRIO INICIAL - TSUNAMI DATA: 12 /07/2024
C3: RESUMO Nota Autoavaliação ▼
C4: Comercial | E4: =G34 -> 41
C5: Marketing | E5: =G46 -> 10
C6: Gestão de Pessoas | E6: =G103 -> 27
C7: Estratégia | E7: =G113 -> 9.5
C10: Societário | G10: Nota Autoavaliação ▼ | I10: NOTA CFE | J10: NOTA MÁX | K10: PONTUAÇÃO MÁXIMA: 100%
C11: Responsável pelas respostas: | G11: =SUM(G15:G20) -> 0 | I11: =SUMIF(J16,">0",I16)+SUMIF(J17,">0",I17)+SUMIF(J18,">0",I18)+SUMIF(J19,">0",I19)+SUMIF(J20,">0",I20)+SUMIF(J15,">0",I15) -> 0 | J11: =SUM(J15:J20) -> 60 | K11: =IFERROR("PONTUAÇÃO REAL: "&(ROUND((IFERROR(I11/J11,"Não se aplica")*100),1)&"%"),0%) -> PONTUAÇÃO REAL: 0%
C12: Responsável do setor:
D14: Item | E14: Perguntas | F14: É aplicável? SIM/NÃO | G14: Autoavaliação (Nota 0 a 10) | H14: Avaliação | I14: Nota Avaliação | J14: Nota Máxima | K14: Observações do Consultor CFE | L14: Melhorias Possíveis
C15: 1.1 | D15: Formalização da sociedade | E15: A sociedade está devidamente formalizada em contrato social? | F15: SIM | G15: 0 | H15: NÃO EXISTE | I15: =IFERROR(VLOOKUP(H15,LISTAS!$B$4:$C$7,2,FALSE),"0") -> 0 | J15: =IF(F15="sim",10,0) -> 10
C16: 1.2 | D16: Quotas da sociedade | E16: Todos os sócios possuem ciências das quotas de cada sócio dentro do negócio? | F16: SIM | G16: 0 | H16: NÃO EXISTE | I16: =IFERROR(VLOOKUP(H16,LISTAS!$B$4:$C$7,2,FALSE),"0") -> 0 | J16: =IF(F16="sim",10,0) -> 10
C17: 1.3 | D17: Governança | E17: São realizadas reuniões mensais com os sócios para análise dos resultados? | F17: SIM | G17: 0 | H17: NÃO EXISTE | I17: =IFERROR(VLOOKUP(H17,LISTAS!$B$4:$C$7,2,FALSE),"0") -> 0 | J17: =IF(F17="sim",10,0) -> 10
C18: 1.4 | D18: Separação das Finanças | E18: Há separação clara dos gastos da pessoa física dos gastos da pessoa jurídica (empresa)? | F18: SIM | G18: 0 | H18: NÃO EXISTE | I18: =IFERROR(VLOOKUP(H18,LISTAS!$B$4:$C$7,2,FALSE),"0") -> 0 | J18: =IF(F18="sim",10,0) -> 10
C19: 1.5 | D19: Pró-Labore | E19: Existe definição do pró-labore mensal dos sócios através de um critério profissional? | F19: SIM | G19: 0 | H19: NÃO EXISTE | I19: =IFERROR(VLOOKUP(H19,LISTAS!$B$4:$C$7,2,FALSE),"0") -> 0 | J19: =IF(F19="sim",10,0) -> 10
C20: 1.6 | D20: Distribuição de Lucros | E20: Existe uma política estabelecida com relação a periodicidade e critério de % na distribuição de lucros? | F20: SIM | G20: 0 | H20: NÃO EXISTE | I20: =IFERROR(VLOOKUP(H20,LISTAS!$B$4:$C$7,2,FALSE),"0") -> 0 | J20: =IF(F20="sim",10,0) -> 10
C22: Tecnologia | G22: Nota Autoavaliação ▼ | I22: NOTA CFE | J22: NOTA MÁX | K22: PONTUAÇÃO MÁXIMA: 100%
C23: Responsável pelas respostas: | G23: =SUM(G27:G31) -> 0 | I23: =SUMIF(J28,">0",I28)+SUMIF(J29,">0",I29)+SUMIF(J30,">0",I30)+SUMIF(J31,">0",I31)+SUMIF(J27,">0",I27) -> 0 | J23: =SUM(J27:J31) -> 50 | K23: =IFERROR("PONTUAÇÃO REAL: "&(ROUND((IFERROR(I23/J23,"Não se aplica")*100),1)&"%"),0%) -> PONTUAÇÃO REAL: 0%
C24: Responsável do setor:
D26: =D$14 -> Item | E26: =E$14 -> Perguntas | F26: =F$14 -> É aplicável? SIM/NÃO | G26: =G$14 -> Autoavaliação (Nota 0 a 10) | H26: =H$14 -> Avaliação | I26: =I$14 -> Nota Avaliação | J26: =J$14 -> Nota Máxima | K26: =K$14 -> Observações do Consultor CFE | L26: =L$14 -> Melhorias Possíveis
C27: 2.1 | D27: Sistemas | E27: A empresa possui sistema para dar suporte à gestão empresarial (ERP), buscando simplificar e automatizar tarefas e ações operacionais? | F27: SIM | G27: 0 | H27: NÃO EXISTE | I27: =IFERROR(VLOOKUP(H27,LISTAS!$B$4:$C$7,2,FALSE),"0") -> 0 | J27: =IF(F27="sim",10,0) -> 10
C28: 2.2 | D28: Suporte | E28: Há treinamento e suporte contínuo quanto ao uso do sistema de gestão (ERP) e outras tecnologias dentro do negócio? | F28: SIM | G28: 0 | H28: NÃO EXISTE | I28: =IFERROR(VLOOKUP(H28,LISTAS!$B$4:$C$7,2,FALSE),"0") -> 0 | J28: =IF(F28="sim",10,0) -> 10
C29: 2.3 | D29: Segurança e Backup | E29: Existe rotina periódica de backup onde os dados da empresa estão armazenados? | F29: SIM | G29: 0 | H29: NÃO EXISTE | I29: =IFERROR(VLOOKUP(H29,LISTAS!$B$4:$C$7,2,FALSE),"0") -> 0 | J29: =IF(F29="sim",10,0) -> 10
C30: 2.4 | D30: Infraestrutura | E30: A empresa possui equipamentos suficientes que suportem ao bom funcionamento da gestão empresarial? | F30: SIM | G30: 0 | H30: NÃO EXISTE | I30: =IFERROR(VLOOKUP(H30,LISTAS!$B$4:$C$7,2,FALSE),"0") -> 0 | J30: =IF(F30="sim",10,0) -> 10
C31: 2.5 | D31: Automação | E31: Existe integração entre a atividade fim do negócio e as atividades financeiras (vendas, compras, estoque, faturamento, contas a receber, cobrança, contas a pagar, relatórios)? | F31: SIM | G31: 0 | H31: NÃO EXISTE | I31: =IFERROR(VLOOKUP(H31,LISTAS!$B$4:$C$7,2,FALSE),"0") -> 0 | J31: =IF(F31="sim",10,0) -> 10
C33: Comercial | G33: Nota Autoavaliação ▼ | I33: NOTA CFE | J33: NOTA MÁX | K33: PONTUAÇÃO MÁXIMA: 100%
C34: Responsável pelas respostas: | G34: =SUM(G38:G43) -> 41 | I34: =SUMIF(J39,">0",I39)+SUMIF(J40,">0",I40)+SUMIF(J41,">0",I41)+SUMIF(J42,">0",I42)+SUMIF(J43,">0",I43)+SUMIF(J38,">0",I38) -> 27 | J34: =SUM(J38:J43) -> 60 | K34: =IFERROR("PONTUAÇÃO REAL: "&(ROUND((IFERROR(I34/J34,"Não se aplica")*100),1)&"%"),0%) -> PONTUAÇÃO REAL: 45%
C35: Responsável do setor:
D37: =D$14 -> Item | E37: =E$14 -> Perguntas | F37: =F$14 -> É aplicável? SIM/NÃO | G37: =G$14 -> Autoavaliação (Nota 0 a 10) | H37: =H$14 -> Avaliação | I37: =I$14 -> Nota Avaliação | J37: =J$14 -> Nota Máxima | K37: =K$14 -> Observações do Consultor CFE | L37: =L$14 -> Melhorias Possíveis
C38: 3.1 | D38: Meta de Vendas | E38: A empresa possui clareza sobre a meta de faturamento necessária para atingir os objetivos desejados pelos sócios? | F38: SIM | G38: 7 | H38: EXISTE (MAS INFORMALMENTE) | I38: =IFERROR(VLOOKUP(H38,LISTAS!$B$4:$C$7,2,FALSE),"0") -> 3 | J38: =IF(F38="sim",10,0) -> 10
C39: 3.2 | D39: CRM | E39: A empresa possui sistema de relacionamento com o cliente que ajude no atingimento da meta de vendas? | F39: SIM | G39: 10 | H39: EXISTE DE FORMA PADRONIZADA (MAS PODE SER MELHORADO) | I39: =IFERROR(VLOOKUP(H39,LISTAS!$B$4:$C$7,2,FALSE),"0") -> 7 | J39: =IF(F39="sim",10,0) -> 10
C40: 3.3 | D40: Precificação dos Serviços | E40: Existe metodologia para precificar os produtos/serviços prestados? | F40: SIM | G40: 7 | H40: EXISTE DE FORMA PADRONIZADA (MAS PODE SER MELHORADO) | I40: =IFERROR(VLOOKUP(H40,LISTAS!$B$4:$C$7,2,FALSE),"0") -> 7 | J40: =IF(F40="sim",10,0) -> 10
C41: 3.4 | D41: Relatórios | E41: Existem relatórios que dão suporte ao acompanhamento diário, semanal e/ou mensal das vendas? | F41: SIM | G41: 7 | H41: EXISTE DE FORMA PADRONIZADA (MAS PODE SER MELHORADO) | I41: =IFERROR(VLOOKUP(H41,LISTAS!$B$4:$C$7,2,FALSE),"0") -> 7 | J41: =IF(F41="sim",10,0) -> 10
C42: 3.5 | D42: Governança | E42: Há reuniões mensais com equipe comercial para apresentação e avaliação dos resultados? | F42: SIM | G42: 5 | H42: EXISTE (MAS INFORMALMENTE) | I42: =IFERROR(VLOOKUP(H42,LISTAS!$B$4:$C$7,2,FALSE),"0") -> 3 | J42: =IF(F42="sim",10,0) -> 10
C43: 3.6 | D43: Indicadores | E43: Existem indicadores de vendas (como número de propostas, taxa de conversão, ticket médio e outros indicadores comerciais)? | F43: SIM | G43: 5 | H43: NÃO EXISTE | I43: =IFERROR(VLOOKUP(H43,LISTAS!$B$4:$C$7,2,FALSE),"0") -> 0 | J43: =IF(F43="sim",10,0) -> 10
C45: Marketing | G45: Nota Autoavaliação ▼ | I45: NOTA CFE | J45: NOTA MÁX | K45: PONTUAÇÃO MÁXIMA: 100%
C46: Responsável pelas respostas: | G46: =SUM(G50:G52) -> 10 | I46: =SUMIF(J51,">0",I51)+SUMIF(J52,">0",I52)+SUMIF(J50,">0",I50) -> 6 | J46: =SUM(J50:J52) -> 30 | K46: =IFERROR("PONTUAÇÃO REAL: "&(ROUND((IFERROR(I46/J46,"Não se aplica")*100),1)&"%"),0%) -> PONTUAÇÃO REAL: 20%
C47: Responsável do setor:
D49: =D$14 -> Item | E49: =E$14 -> Perguntas | F49: =F$14 -> É aplicável? SIM/NÃO | G49: =G$14 -> Autoavaliação (Nota 0 a 10) | H49: =H$14 -> Avaliação | I49: =I$14 -> Nota Avaliação | J49: =J$14 -> Nota Máxima | K49: =K$14 -> Observações do Consultor CFE | L49: =L$14 -> Melhorias Possíveis
...

Sheet Comercial
A1: DIAGNÓSTICO EMPRESARIAL
C3: =Resultados!$D$5 -> Comercial
C22: Principais Oportunidades de Melhoria
C24: Registrar nesta perspectiva o faturamento atual do cliente para medir o crescimento
C25: Recomendar o uso de um CRM para apoio no atingimento das metas comerciais que garantirão o resultado financeiro
C26: Elaborar método de precificação para cada tipo de produto/serviço
C27: Recomendar relatórios de vendas para a equipe comercial/sócios possam acompanhar as meta comerciais
C28: Recomendar reuniões de acompanhamento para a equipe de de vendas/comercial
C29: Recomendar implantação de indicadores comerciais

Sheet Marketing
A1: DIAGNÓSTICO EMPRESARIAL
C3: =Resultados!$D$6 -> Marketing
C22: Principais Oportunidades de Melhoria
C24: Elaborar objetivos e metas de Retorno Sobre Investimento em Markting para os próximos 12 meses
C25: Contratar assessoria de marketing (colaborador exclusivo ou empresa terceirizada)
C26: Divulgar o planejamento das ações para os colaboradores através de uma agenda fixa (semanal, mensal, anual)

Sheet Estratégia
A1: DIAGNÓSTICO EMPRESARIAL
C3: =Resultados!$D$12 -> Estratégia
C22: Principais Oportunidades de Melhoria
C24: Elaborar planos para novos serviços ou de expansão para novas praças
C25: Analisar Forças, Fraquezas, Ameaças e Oportunidades do setor (SWOT/FOFA)
C26: Desenhar o Plano de Negócios (Canvas)
C27: Elaborar a viabilidade econômico-financeiro de uma nova unidade/filial da empresa cliente
C28: Definir as metas para atingir os objetivos da empresa e dos sócios

Sheet Pessoas
A1: DIAGNÓSTICO EMPRESARIAL
C3: =Resultados!$D$11 -> Gestão de Pessoas
C22: Principais Oportunidades de Melhoria
C24: Sugerir premiações aos colaboradores mediante atingimento de resultados anuais
C25: Sugerir benefícios como reembolso de academia, plano de saúde, plano odontológico, seguro de vida aos colaboradores
C26: Realizar o recolhimento de todas as obrigações e encargos trabalhistas (a fim de evitar qualquer ação futura contra a empresa)

Sheet Resultados
A1: DIAGNÓSTICO EMPRESARIAL
C2: RESULTADO CONSOLIDADO
C3: 1 | D3: ='Diagnóstico'!C10 -> Societário | G3: =IFERROR('Diagnóstico'!I11/'Diagnóstico'!J11,0%) -> 0 | K3: 1
C4: 2 | D4: ='Diagnóstico'!C22 -> Tecnologia | G4: =IFERROR('Diagnóstico'!I23/'Diagnóstico'!J23,0%) -> 0 | K4: 1
C5: 3 | D5: ='Diagnóstico'!C33 -> Comercial | G5: =IFERROR('Diagnóstico'!I34/'Diagnóstico'!J34,0%) -> 0.45 | K5: 1
C6: 4 | D6: ='Diagnóstico'!C45 -> Marketing | G6: =IFERROR('Diagnóstico'!I46/'Diagnóstico'!J46,0%) -> 0.2 | K6: 1
C7: 5 | D7: ='Diagnóstico'!C54 -> Financeiro | G7: =IFERROR('Diagnóstico'!I55/'Diagnóstico'!J55,0%) -> 0 | K7: 1
C8: 6 | D8: ='Diagnóstico'!C67 -> Controladoria | G8: =IFERROR('Diagnóstico'!I68/'Diagnóstico'!J68,0%) -> 0 | K8: 1
C9: 7 | D9: ='Diagnóstico'!C82 -> Fiscal | G9: =IFERROR('Diagnóstico'!I83/'Diagnóstico'!J83,0%) -> 0 | K9: 1
C10: 8 | D10: ='Diagnóstico'!C92 -> Contábil | G10: =IFERROR('Diagnóstico'!I93/'Diagnóstico'!J93,0%) -> 0 | K10: 1
C11: 9 | D11: ='Diagnóstico'!C102 -> Gestão de Pessoas | G11: =IFERROR('Diagnóstico'!I103/'Diagnóstico'!J103,0%) -> 0.5 | K11: 1
C12: 10 | D12: ='Diagnóstico'!C112 -> Estratégia | G12: =IFERROR('Diagnóstico'!I113/'Diagnóstico'!J113,0%) -> 0.23333333 | K12: 1
C15: Resultados por Perspectiva

Sheet Total
A1: DIAGNÓSTICO EMPRESARIAL
C2: CONSOLIDADO
C5: =Resultados!D3 -> Societário | D5: =Resultados!D4 -> Tecnologia | E5: =Resultados!D5 -> Comercial | F5: =Resultados!D6 -> Marketing | G5: =Resultados!D7 -> Financeiro | H5: =Resultados!D8 -> Controladoria | I5: =Resultados!D9 -> Fiscal | J5: =Resultados!D10 -> Contábil | K5: =Resultados!D11 -> Gestão de Pessoas | L5: =Resultados!D12 -> Estratégia
C6: =IFERROR(Resultados!G3,0%) -> 0 | D6: =IFERROR(Resultados!G4,0%) -> 0 | E6: =IFERROR(Resultados!G5,0%) -> 0.45 | F6: =IFERROR(Resultados!G6,0%) -> 0.2 | G6: =IFERROR(Resultados!G7,0%) -> 0 | H6: =IFERROR(Resultados!G8,0%) -> 0 | I6: =IFERROR(Resultados!G9,0%) -> 0 | J6: =IFERROR(Resultados!G10,0%) -> 0 | K6: =IFERROR(Resultados!G11,0%) -> 0.5 | L6: =IFERROR(Resultados!G12,0%) -> 0.23333333
C7: =1-C6 -> 1 | D7: =1-D6 -> 1 | E7: =1-E6 -> 0.55 | F7: =1-F6 -> 0.8 | G7: =1-G6 -> 1 | H7: =1-H6 -> 1 | I7: =1-I6 -> 1 | J7: =1-J6 -> 1 | ... L7: =1-L6 -> 0.76666667
C10: NÍVEL DE EXCELÊNCIA NA GESTÃO EMPRESARIAL | G10: =AVERAGE(C6:L6) -> 0.13833333 | I10: PILARES DE ALAVANCAGEM E CRESCIMENTO ISP4 CONSULTORIA | L10: =AVERAGE(E6,F6,K6,L6) -> 0.34583333
G11: =G10 -> 0.13833333

Sheet Societário
A1: DIAGNÓSTICO EMPRESARIAL
C3: ='Diagnóstico'!C10 -> Societário
C22: Principais Oportunidades de Melhoria
C24: Recomendar a formalização dos sócios que não constam em contrato social
C25: Definir quotas sociais e os percentuais entre os sócios
C26: Realizar reunião mensal com os sócios e diretores para acompanhamento dos resultados alcançados em todas as esferas
C27: Definir critérios e valores de pró-labores para os sócios que possuem função executiva no negócio
C28: Definir critérios, valores e periodicidade para a distribuição de lucros (quando houver)

Sheet Tecnologia
A1: DIAGNÓSTICO EMPRESARIAL
C3: =Resultados!$D$4 -> Tecnologia
C22: Principais Oportunidades de Melhoria
C24: Recomendar implantação de um software de gestão financeira capaz de realizar o controle das movimentações de entradas e saídas
C25: Sugerir programa de treinamento contínuo para os colaboradores
C26: Recomendar manter os dados em ambiente protegido (preferencial em nuvem)
C27: Recomendar integração e automação das atividades financeiras do negócio

Sheet Financeiro
A1: DIAGNÓSTICO EMPRESARIAL
C3: =Resultados!$D$7 -> Financeiro
C22: Principais Oportunidades de Melhoria
C24: Estruturar um plano de contas gerencial para o negócio
C25: Definir rotinas e processos do contas a pagar
C26: Definir rotinas e processos do contas a receber
C27: Estruturar processo de conferência e conciliação bancária diária
C28: Implantar o fluxo de caixa (diário, semanal, quinzenal, mensal, anual)
C29: Elaborar políticas de crédito especificando formas de pagamento e limites para determinados perfis de clientes
C30: Recomendar relatórios financeiros através do software de gestão que possam auxiliar no atingimento das metas de resultado

Sheet Controladoria
A1: DIAGNÓSTICO EMPRESARIAL
C3: =Resultados!$D$8 -> Controladoria
C22: Principais Oportunidades de Melhoria
C24: Definir em valor (R$) quanto a empresa precisa ter em caixa para suportar no mínimo 4 meses sem vendas (reserva de emergência)
C25: Definir a meta de resultado - DRE (mensal, semestral e anual)
C26: Acompanhar o orçamento mensalmente (DRE e Caixa)
C27: Definir Ponto de Equilíbrio Econômico
C28: Realizar acompanhamento de orçado vs realizado
C29: Realizar análises verticais e horizontais dos grupos de contas e análise das variações
C30: Recomendar implantação de indicadores financeiros (Margem de Contribuição, EBITDA, Lucratividade, SG&A)

Sheet Fiscal
A1: DIAGNÓSTICO EMPRESARIAL
C3: =Resultados!$D$9 -> Fiscal
C22: Principais Oportunidades de Melhoria
C24: Acionar contabilidade para validação do melhor regime de tribuitação (Planejamento Tributário)
C25: Realizar o recolhimento dos tributos mensalmente ou a medida que houver o fato gerador
C26: Realizar a apuração fiscal de 100% das vendas
C27: Recomendar automação entre o módulo de vendas (faturamento) e o financeiro

Sheet Contábil
A1: DIAGNÓSTICO EMPRESARIAL
C3: =Resultados!$D$10 -> Contábil
C22: Principais Oportunidades de Melhoria
C24: Solicitar balancete e DRE contábil da contabilidade mensalmente
C25: Realizar análise entre DRE do financeiro/controladoria e da contabilidade
C26: Enviar mensalmente os extratos bancários e documentos comprobatórios (notas fiscais, contratos, cupons fiscais) para a contabilidade
C27: Realizar reunião mensal com a contabilidade para cumprimento das obrigações acessórias

Sheet Protocolo
A1: DIAGNÓSTICO EMPRESARIAL
C4: Protocolo de Entrega do Produto
C6: AO NOME DA EMPRESA, inscrita no CNPJ sob o nº XX.XXX.XXX/0001-XX, estabelecida na Rua, nº XXX, Complemento - Cidade/UF, declara ter recebido da FIRMA DE CONSULTORIA XXXXX, inscrito no CNPJ sob o nº XX.XXX.XXX/0001-XX, os seguintes produtos referentes ao contrato de Consultoria, conforme descritos abaixo:
C12: Produto | G12: Especificação
C14: 1 | D14: Relatório de Diagnóstico | G14: Este documento contempla: a) os resultados obtidos da EMPRESA XXX; b) sugestões de melhorias nos aspectos abordados no processo de diagnóstico.
A16: i
C23: 2 | D23: Apresentação Final do Diagnóstico realizado para a Diretoria | G23: Este documento contempla: a) Sumário Executivo; b) Análise de Evidências Financeiras; c) Conclusões e Recomendações; e d) Proposta de Contrato de Consultoria em Gestão.
C28: 3 | D28: Mídia com as informações entregues | G28: Esta mídia contempla: arquivo em .pdf da Apresentação Final do Diagnóstico e Relatório de Diagnóstico
C35: Cidade/UF, XX de XXXX de 2023
C39: NOME DO CLIENTE

Sheet LISTAS
B3: LEGENDA | C3: NOTA
B4: NÃO EXISTE | C4: 0
B5: EXISTE (MAS INFORMALMENTE) | C5: 3
B6: EXISTE DE FORMA PADRONIZADA (MAS PODE SER MELHORADO) | C6: 7
B7: EXISTE E FUNCIONA PERFEITAMENTE | C7: 10

Sheet Apoio
B2: ='Diagnóstico'!C10 -> Societário | C2: =IFERROR('Diagnóstico'!I11/'Diagnóstico'!J11,0) -> 0 | D2: =1-C2 -> 1 | F2: ='Diagnóstico'!C22 -> Tecnologia | G2: =IFERROR('Diagnóstico'!I23/'Diagnóstico'!J23,0) -> 0 | H2: =1-G2 -> 1 | J2: ='Diagnóstico'!C33 -> Comercial | K2: =IFERROR('Diagnóstico'!I34/'Diagnóstico'!J34,0) -> 0.45 | L2: =1-K2 -> 0.55 | N2: ='Diagnóstico'!C45 -> Marketing | O2: =IFERROR('Diagnóstico'!I46/'Diagnóstico'!J46,0) -> 0.2 | P2: =1-O2 -> 0.8 | R2: ='Diagnóstico'!C54 -> Financeiro | S2: =IFERROR('Diagnóstico'!I55/'Diagnóstico'!J55,0) -> 0 | T2: =1-S2 -> 1 | V2: ='Diagnóstico'!C67 -> Controladoria | W2: =IFERROR('Diagnóstico'!I68/'Diagnóstico'!J68,0) -> 0 | X2: =1-W2 -> 1 | Z2: ='Diagnóstico'!C82 -> Fiscal | AA2: =IFERROR('Diagnóstico'!I83/'Diagnóstico'!J83,0) -> 0 | AB2: =1-AA2 -> 1 | AD2: ='Diagnóstico'!C92 -> Contábil | AE2: =IFERROR('Diagnóstico'!I93/'Diagnóstico'!J93,0) -> 0 | AF2: =1-AE2 -> 1 | AH2: ='Diagnóstico'!C102 -> Gestão de Pessoas | AI2: =IFERROR('Diagnóstico'!I103/'Diagnóstico'!J103,0) -> 0.5 | AJ2: =1-AI2 -> 0.5 | AL2: ='Diagnóstico'!C112 -> Estratégia | AM2: =IFERROR('Diagnóstico'!I113/'Diagnóstico'!J113,0) -> 0.23333333 | AN2: =1-AM2 -> 0.76666667
B3: ='Diagnóstico'!D15 -> Formalização da sociedade | C3: =IFERROR('Diagnóstico'!I15/'Diagnóstico'!J15,0) -> 0 | D3: =1-C3 -> 1 | F3: ='Diagnóstico'!D27 -> Sistemas | G3: =IFERROR('Diagnóstico'!I27/'Diagnóstico'!J27,0) -> 0 | H3: =1-G3 -> 1 | J3: ='Diagnóstico'!D38 -> Meta de Vendas | K3: =IFERROR('Diagnóstico'!I38/'Diagnóstico'!J38,0) -> 0.3 | L3: =1-K3 -> 0.7 | N3: ='Diagnóstico'!D50 -> Planejamento | O3: =IFERROR('Diagnóstico'!I50/'Diagnóstico'!J50,0) -> 0.3 | P3: =1-O3 -> 0.7 | R3: ='Diagnóstico'!D59 -> Plano de Contas | S3: =IFERROR('Diagnóstico'!I59/'Diagnóstico'!J59,0) -> 0 | T3: =1-S3 -> 1 | V3: ='Diagnóstico'!D72 -> Capital de Giro | W3: =IFERROR('Diagnóstico'!I72/'Diagnóstico'!J72,0) -> 0 | X3: =1-W3 -> 1 | Z3: ='Diagnóstico'!D87 -> Planejamento Tributário | AA3: =IFERROR('Diagnóstico'!I87/'Diagnóstico'!J87,0) -> 0 | AB3: =1-AA3 -> 1 | AD3: ='Diagnóstico'!D97 -> Balancete e DRE | AE3: =IFERROR('Diagnóstico'!I97/'Diagnóstico'!J97,0) -> 0 | AF3: =1-AE3 -> 1 | AH3: ='Diagnóstico'!D107 -> Plano de Cargos e Salários | AI3: =IFERROR('Diagnóstico'!I107/'Diagnóstico'!J107,0) -> 0.7 | AJ3: =1-AI3 -> 0.3 | AL3: ='Diagnóstico'!D117 -> Inovação | AM3: =IFERROR('Diagnóstico'!I117/'Diagnóstico'!J117,0) -> 0.7 | AN3: =1-AM3 -> 0.3
B4: ='Diagnóstico'!D16 -> Quotas da sociedade | C4: =IFERROR('Diagnóstico'!I16/'Diagnóstico'!J16,0) -> 0 | D4: =1-C4 -> 1 | F4: ='Diagnóstico'!D28 -> Suporte | G4: =IFERROR('Diagnóstico'!I28/'Diagnóstico'!J28,0) -> 0 | H4: =1-G4 -> 1 | J4: ='Diagnóstico'!D39 -> CRM | K4: =IFERROR('Diagnóstico'!I39/'Diagnóstico'!J39,0) -> 0.7 | L4: =1-K4 -> 0.3 | N4: ='Diagnóstico'!D51 -> Assessoria de Marketing | O4: =IFERROR('Diagnóstico'!I51/'Diagnóstico'!J51,0) -> 0.3 | P4: =1-O4 -> 0.7 | R4: ='Diagnóstico'!D60 -> Contas a Pagar | S4: =IFERROR('Diagnóstico'!I60/'Diagnóstico'!J60,0) -> 0 | T4: =1-S4 -> 1 | V4: ='Diagnóstico'!D73 -> Meta Financeira | W4: =IFERROR('Diagnóstico'!I73/'Diagnóstico'!J73,0) -> 0 | X4: =1-W4 -> 1 | Z4: ='Diagnóstico'!D88 -> Recolhimento de Tributos | AA4: =IFERROR('Diagnóstico'!I88/'Diagnóstico'!J88,0) -> 0 | AB4: =1-AA4 -> 1 | AD4: ='Diagnóstico'!D98 -> Automação | AE4: =IFERROR('Diagnóstico'!I98/'Diagnóstico'!J98,0) -> 0 | AF4: =1-AE4 -> 1 | AH4: ='Diagnóstico'!D108 -> Benefícios | AI4: =IFERROR('Diagnóstico'!I108/'Diagnóstico'!J108,0) -> 0 | AJ4: =1-AI4 -> 1 | AL4: ='Diagnóstico'!D118 -> Crescimento e Expansão | AM4: =IFERROR('Diagnóstico'!I118/'Diagnóstico'!J118,0) -> 0 | AN4: =1-AM4 -> 1
B5: ='Diagnóstico'!D17 -> Governança | C5: =IFERROR('Diagnóstico'!I17/'Diagnóstico'!J17,0) -> 0 | D5: =1-C5 -> 1 | F5: ='Diagnóstico'!D29 -> Segurança e Backup | G5: =IFERROR('Diagnóstico'!I29/'Diagnóstico'!J29,0) -> 0 | H5: =1-G5 -> 1 | J5: ='Diagnóstico'!D40 -> Precificação dos Serviços | K5: =IFERROR('Diagnóstico'!I40/'Diagnóstico'!J40,0) -> 0.7 | L5: =1-K5 -> 0.3 | N5: ='Diagnóstico'!D52 -> Endomarketing | O5: =IFERROR('Diagnóstico'!I52/'Diagnóstico'!J52,0) -> 0 | P5: =1-O5 -> 1 | R5: ='Diagnóstico'!D61 -> Contas a Receber | S5: =IFERROR('Diagnóstico'!I61/'Diagnóstico'!J61,0) -> 0 | T5: =1-S5 -> 1 | V5: ='Diagnóstico'!D74 -> Orçamento | W5: =IFERROR('Diagnóstico'!I74/'Diagnóstico'!J74,0) -> 0 | X5: =1-W5 -> 1 | Z5: ='Diagnóstico'!D89 -> Apuração Fiscal | AA5: =IFERROR('Diagnóstico'!I89/'Diagnóstico'!J89,0) -> 0 | AB5: =1-AA5 -> 1 | AD5: ='Diagnóstico'!D99 -> Documentação | AE5: =IFERROR('Diagnóstico'!I99/'Diagnóstico'!J99,0) -> 0 | AF5: =1-AE5 -> 1 | AH5: ='Diagnóstico'!D109 -> Obrigações Trabalhistas | AI5: =IFERROR('Diagnóstico'!I109/'Diagnóstico'!J109,0) -> 1 | AJ5: =1-AI5 -> 0 | AL5: ='Diagnóstico'!D119 -> Estratégia | AM5: =IFERROR('Diagnóstico'!I119/'Diagnóstico'!J119,0) -> 0 | AN5: =1-AM5 -> 1
B6: ='Diagnóstico'!D18 -> Separação das Finanças | C6: =IFERROR('Diagnóstico'!I18/'Diagnóstico'!J18,0) -> 0 | D6: =1-C6 -> 1 | F6: ='Diagnóstico'!D30 -> Infraestrutura | G6: =IFERROR('Diagnóstico'!I30/'Diagnóstico'!J30,0) -> 0 | H6: =1-G6 -> 1 | J6: ='Diagnóstico'!D41 -> Relatórios | K6: =IFERROR('Diagnóstico'!I41/'Diagnóstico'!J41,0) -> 0.7 | L6: =1-K6 -> 0.3 | R6: ='Diagnóstico'!D62 -> Conciliação Bancária | S6: =IFERROR('Diagnóstico'!I62/'Diagnóstico'!J62,0) -> 0 | T6: =1-S6 -> 1 | V6: ='Diagnóstico'!D75 -> Ponto de Equilíbrio | W6: =IFERROR('Diagnóstico'!I75/'Diagnóstico'!J75,0) -> 0 | X6: =1-W6 -> 1 | Z6: ='Diagnóstico'!D90 -> Automação | AA6: =IFERROR('Diagnóstico'!I90/'Diagnóstico'!J90,0) -> 0 | AB6: =1-AA6 -> 1 | AD6: ='Diagnóstico'!D100 -> Planejamento | AE6: =IFERROR('Diagnóstico'!I100/'Diagnóstico'!J100,0) -> 0 | AF6: =1-AE6 -> 1 | AH6: ='Diagnóstico'!D110 -> PLR | AI6: =IFERROR('Diagnóstico'!I110/'Diagnóstico'!J110,0) -> 0.3 | AJ6: =1-AI6 -> 0.7
B7: ='Diagnóstico'!D19 -> Pró-Labore | C7: =IFERROR('Diagnóstico'!I19/'Diagnóstico'!J19,0) -> 0 | D7: =1-C7 -> 1 | F7: ='Diagnóstico'!D31 -> Automação | G7: =IFERROR('Diagnóstico'!I31/'Diagnóstico'!J31,0) -> 0 | H7: =1-G7 -> 1 | J7: ='Diagnóstico'!D42 -> Governança | K7: =IFERROR('Diagnóstico'!I42/'Diagnóstico'!J42,0) -> 0.3 | L7: =1-K7 -> 0.7 | R7: ='Diagnóstico'!D63 -> Fluxo de Caixa | S7: =IFERROR('Diagnóstico'!I63/'Diagnóstico'!J63,0) -> 0 | T7: =1-S7 -> 1 | V7: ='Diagnóstico'!D76 -> Gestão Orçamentária | W7: =IFERROR('Diagnóstico'!I76/'Diagnóstico'!J76,0) -> 0 | X7: =1-W7 -> 1
B8: ='Diagnóstico'!D20 -> Distribuição de Lucros | C8: =IFERROR('Diagnóstico'!I20/'Diagnóstico'!J20,0) -> 0 | D8: =1-C8 -> 1 | J8: ='Diagnóstico'!D43 -> Indicadores | K8: =IFERROR('Diagnóstico'!I43/'Diagnóstico'!J43,0) -> 0 | L8: =1-K8 -> 1 | R8: ='Diagnóstico'!D64 -> Crédito e Cobrança | S8: =IFERROR('Diagnóstico'!I64/'Diagnóstico'!J64,0) -> 0 | T8: =1-S8 -> 1 | V8: ='Diagnóstico'!D77 -> Gestão de Custos e Despesas | W8: =IFERROR('Diagnóstico'!I77/'Diagnóstico'!J77,0) -> 0 | X8: =1-W8 -> 1
R9: ='Diagnóstico'!D65 -> Relatórios | S9: =IFERROR('Diagnóstico'!I65/'Diagnóstico'!J65,0) -> 0 | T9: =1-S9 -> 1 | V9: ='Diagnóstico'!D78 -> Análise Vertical / Horizontal | W9: =IFERROR('Diagnóstico'!I78/'Diagnóstico'!J78,0) -> 0 | X9: =1-W9 -> 1
V10: ='Diagnóstico'!D79 -> Indicadores | W10: =IFERROR('Diagnóstico'!I79/'Diagnóstico'!J79,0) -> 0 | X10: =1-W10 -> 1
V11: ='Diagnóstico'!D80 -> Relatórios | W11: =IFERROR('Diagnóstico'!I80/'Diagnóstico'!J80,0) -> 0 | X11: =1-W11 -> 1
